Workbook
Name I2xL166: #REF!
Name Q2.Q222: padron_prevecion!$Q$222

Sheet DatosPersonales
A1: id: | B1: Apellido: | C1: Nombre | D1: D.n.i: | E1: Nacionalidad: | F1: Género: | G1: Domicilio (Calle y n°): | H1: Cod. Postal: | I1: Provincia: | J1: Estudios: | K1: Titulo / Carrera: | L1: Estado Civil: | M1: Localidad: | N1: E-Mail: | O1: Tel. Contacto: | P1: Fecha Nacimiento:
A2: 21726330 | B2: battafarano | C2: amelia andrea | D2: 21726330 | N2: andrius_1970@hotmail.com | O2: 1144271929 | P2: 25771
A3: 32436304 | B3: arroyo | C3: elizabeth beatriz | D3: 32436304 | N3: elizabeth_arroyo25@hotmail.com | P3: 31527
A4: 31963497 | B4: aranda | C4: natalia veronica | D4: 31963497 | E4: argentina | F4: femenino | G4: pola 2952 | H4: 1439 | I4: bsas | J4: terciario | K4: tecnica radiologa | L4: casada | M4: caba | N4: aranda_natalia@hotmail.com.ar | O4: 1156294264 | P4: 0
A5: 25379033 | B5: amaya | C5: mariela cecilia | D5: 25379033 | E5: argentina | F5: femenino | G5: el hornero 403 | H5: 1408 | I5: bsas | J5: secundario | K5: bachiller contable | L5: divociada | M5: caba | N5: marielaceciliaamaya@hotmail.com | O5: 1126921416 | P5: 27877
A6: 38184089 | B6: amaya | C6: erika elizabeth | D6: 38184089 | M6: caba | O6: 1127191780 | P6: 0
A7: 38894668 | B7: alegre | C7: daniela | D7: 38894668 | M7: caba | N7: danielaoriana68@gmail.com | O7: 1153205634 | P7: 34752
A8: 39114453 | B8: ale | C8: micaela ayelen | D8: 39114453 | M8: caba | N8: micaale40@gmail.com | O8: 1133985337 | P8: 34957
A9: 26678242 | B9: albornoz | C9: victor omar | D9: 26678242 | M9: caba | N9: albornoz78victor@gmail.com | O9: 1136163590 | P9: 28848
A10: 42012262 | B10: acosta | C10: belen teresa | D10: 42012262 | F10: femenino | I10: bsas | J10: secundario | M10: caba | N10: belenmilena1311@hotmail.com | O10: 1128788904 | P10: 36322
A11: 33155103 | B11: romero | C11: irina | D11: 33155103 | E11: argentina | F11: femenino | H11: 1406 | I11: bsas | J11: terciario | K11: terciario en estraccion | L11: soltera | M11: caba | N11: romeroirinauma19@gmail.com | O11: 1165037377 | P11: 31961
A12: 35538835 | B12: ruiz | C12: pablo nahuel | D12: 35538835 | E12: argentino | F12: masculino | G12: las calas 780 | H12: 1778 | I12: bsas | J12: secundario | L12: soltero | M12: ciudad evita | N12: nahuelruiz009@gmail.com | O12: 1165851734 | P12: 33586
A13: 93996095 | B13: felipe lima | C13: aidee deysi | D13: 93996095 | E13: boliviana | F13: femenino | G13: av. Castañares 4650 | H13: 1439 | I13: bsas | J13: terciario | K13: sociologa social | L13: soltera | M13: caba | N13: aideefelipe1977@gmail.com | O13: 1128666648 | P13: 28260
A14: 94842492 | B14: olaya piña | C14: laly del pilar | D14: 94842492 | E14: paraguaya | F14: femenino | G14: hernandarias | H14: 1164 | I14: basa | J14: universitario | K14: licenciado en seguridad publica | L14: soltera | M14: caba | N14: polayalp39@gmail.com | O14: 1154169265 | P14: 33484
A15: 95102089 | B15: ferro rodriguez | C15: maria elena | D15: 95102089 | E15: uruguaya | F15: femenino | G15: fonrouge | H15: 1434 | I15: bsas | J15: universitario | L15: divorciada | M15: caba | N15: marielen1031@hotmail.com | O15: 1150420061 | P15: 27698
A16: 95189729 | B16: gutierrez quispe | C16: griselda | D16: 95189729 | E16: boliviana | F16: femenino | G16: villa 20 | J16: secundario | L16: soltera | M16: caba | N16: chiiguisguty@gmain.com | O16: 1124936411 | P16: 30644
A17: 20009014 | B17: fernandez | C17: mariana | D17: 20009014 | E17: argentina | F17: femenino | G17: galvan 3556 | H17: 1431 | I17: bsas | J17: universitario | K17: psicologia(en curso) | L17: casada | M17: caba | O17: 1144937482 | P17: 24856
A18: 29635937 | B18: dugour | C18: cecilia paola | D18: 29635937 | E18: argentina | F18: femenina | G18: catrilo 546 | H18: 1752 | I18: bsas | J18: secundario | L18: soltera | M18: lomas del mirador | N18: lachechu.lachechu@gmail.com | O18: 1141697938 | P18: 30139
A19: 39471585 | B19: divito | C19: florencia belen | D19: 39471585 | E19: argentina | F19: femenino | G19: 11 de septiembre 545 | H19: 1704 | I19: bsas | J19: secundario | K19: bachiller en ciencias sociales y humanidades | L19: soltera | M19: ramos mejia | N19: floordivito@gmail.com | O19: 1151781882 | P19: 35096
A20: 43817038 | B20: guitierrez | C20: aylin silvia | D20: 43817038 | E20: argentina | F20: femenina | G20: montiel 3912 | H20: 1439 | I20: bsas | J20: primario | L20: soltera | M20: lugano | N20: aylingutierrez74@gmail.com | O20: 1138174900 | P20: 37370
A21: 44486458 | B21: alvarez | C21: miranda | D21: 44486458 | E21: argentina | F21: femenino | G21: mariano acosta 3500 | H21: 1437 | I21: bsas | J21: secundario | K21: bachiller en ciencias naturales | L21: soltera | M21: villa soldati | N21: sabriialvarez06@gmail.com | O21: 1154166856 | P21: 0
A22: 36685920 | B22: davico castañeira | C22: nazareno martin | D22: 36685920 | E22: argentino | F22: masculino | G22: dellepiane 4540 | H22: 1439 | I22: bsas | J22: secundario | K22: perito comercial | L22: soltero | M22: capital federal | N22: nazareno.davico@live.com | O22: 1137817717 | P22: 0
A23: 25060598 | B23: melgarejo | C23: viviana noemi | D23: 25060598 | E23: argentina | F23: femenino | G23: alfredo palacios 4146 | H23: 1752 | I23: bsas | J23: secundario | K23: bachiller | L23: soltera | M23: lomas del mirador | N23: melgarejovivi88@gmail.com | O23: 1168243462 | P23: 0
A24: 31896263 | B24: nogueira | C24: diego marcelo | D24: 31896263 | E24: argentino | F24: masculino | G24: san pedro 4751 | H24: 1407 | I24: bsas | J24: secundario | K24: contable | L24: soltero | M24: caba | N24: diegoluli21@gmail | O24: 1140450018 | P24: 31465
A25: 32554313 | B25: bonomo | C25: yamila maria | D25: 32554313 | E25: argentina | F25: femenino | G25: jose e rodo 4387 | H25: 1407 | I25: bsas | J25: universitario | K25: cursando abogacia | L25: separada | M25: caba | N25: yamilabonomo@hotmail.com | O25: 1160341130 | P25: 31644
A26: 33905319 | B26: herrera | C26: gaston | D26: 33905319 | E26: argentino | F26: masculino | G26: roldan 2575 | H26: 1759 | I26: bsas | J26: secundario | L26: casado | M26: gonzalez catan | N26: herreragas2021@gmail.com | P26: 0
A27: 31302984 | B27: sinchicay | C27: nelida del valle | D27: 31302984 | E27: argentina | F27: femenino | G27: carlos encina 4595 | H27: 1757 | I27: bsas | J27: secundario | K27: bachiller en economia y gestion | L27: soltera | M27: laferrere | N27: nelus872009@hotmail.com | O27: 1130700402 | P27: 30966
A28: 34423850 | B28: mariani | C28: melina giselle | D28: 34423850 | E28: argentina | F28: femenino | G28: primera junta 5512 | H28: 1440 | I28: bsas | J28: secundario | L28: soltera | M28: caba | N28: melinamariani@hotmail.com | O28: 1144171447 | P28: 32546
A29: 32616368 | B29: melgarejo | C29: gabriela romina | D29: 32616368 | E29: argentina | F29: femenino | G29: mz63 vores san javier | H29: 1763 | I29: bsas | J29: secundario | L29: soltera | M29: virrey del pino | N29: gabielarominamelgarejo2@gmail | P29: 0
A30: 43241630 | B30: silva borda | C30: nicolas rodrigo | D30: 43241630 | E30: argentino | F30: masculino | G30: albareño 2811 | H30: 1439 | I30: bsas | J30: secundario | L30: soltero | M30: capital federal | N30: nikkoxeneixe@gmail.com | O30: 1173662195 | P30: 37013
A31: 30440348 | B31: gimenez | C31: monica susana | D31: 30440348 | E31: argentina | F31: femenino | G31: arozarena | H31: 1770 | I31: bsas | J31: universitario | K31: psicopedagogia | L31: casada | M31: tapatiales | N31: moni_181275@hotmail.com | O31: 1160234773 | P31: 27746
A32: 30211914 | B32: jaime | C32: emilse solange | D32: 30211914 | E32: argentina | F32: femenino | G32: remedios 5523 pb | H32: 1440 | I32: bsas | J32: secundario | K32: bachillerato comercial | L32: soltera | M32: mataderos | N32: emilse_jaime@hotmail.com | O32: 1539209596 | P32: 30410
A33: 40873767 | B33: tuzes | C33: maria ester | D33: 40873767 | E33: argentina | F33: femenino | G33: riogallegos 1895 | H33: 1832 | I33: bsas | J33: secundario | L33: soltera | M33: lomas de zamora | N33: martuzesesterm@gmail.com | O33: 1140554236 | P33: 32635
A34: 94075255 | B34: benittez | C34: mirian celeste | D34: 94075255 | E34: paraguay | F34: femenino | G34: viilla 15 n 26bis casa 13 | H34: 1439 | I34: bsas | J34: secundario | L34: casada | M34: caba | N34: micebe2017@gmail.com | O34: 1161619314 | P34: 27897
A35: 29064893 | B35: aquino | C35: emilio javier | D35: 29064893 | E35: argentino | F35: masculino | G35: calle 29 6266 | H35: 1886 | I35: bsas | J35: secundario | K35: arte | L35: casado | M35: berazategui | N35: aquinoemiliojavier@gmail.com | O35: 1125208147 | P35: 29845
A36: 37388128 | B36: caballero reyna | C36: manuel ignacio | D36: 37388128 | N36: manucaballeroreyna2015@gmail.com | O36: 1169729268
A37: 31403780 | B37: cardozo | C37: gladys mabel | D37: 31403780 | N37: mabu21@gmail.com | O37: 1137920163 | P37: 31012
A38: 41917769 | B38: cipriano | C38: facundo nicolas | D38: 41917769 | N38: ciprianofacundonicolas@gmail.com | O38: 1134858925
A39: 22826482 | B39: corarelu | C39: alejandra | D39: 22826482 | N39: alejandracorarelu@hotmail.com | O39: 1166482926 | P39: 26532
A40: 37060301 | B40: coronel | C40: alejandra noemi | D40: 37060301 | N40: coronel.alejandra21n@gmail.com | P40: 34084
...

Sheet DatosLaborales
A1: id: | B1: clave_foranea | C1: N° De Legajo | D1: N° De Cuil: | E1: Domicilio del lugar de Trabajo: (Calle y n°) | F1: Localidad: | G1: Motivo de Afiliación: | H1: Organismo que liquida su haber | I1: Organismo donde trabaja: | J1: Obra Social: | K1: N° de Afiliado: | L1: Fecha de Alta: | M1: Relacion de Dependencia | N1: Inicio Actividad: | O1: Años en Actividad: | P1: renuncio | Q1: tiene_ficha_pdf
A2: 1 | B2: 21726330 | C2: 127 | D2: 34999032089 | E2: bolivar 189 | F2: caba | G2: Gremiales | H2: g.caba | I2: prevencion de la ciudad | M2: planta permanente | N2: 42767 | O2: =YEAR(NOW())-YEAR(N2) -> 8 | P2: 1 | Q2: {=XLOOKUP(C2,fichas_pdf[ap],fichas_pdf[tiene],"no tiene en pdf",0,1)} -> no tiene en pdf
A3: 2 | B3: 32436304 | C3: 1575 | D3: 34999032089 | E3: bolivar 190 | F3: caba | G3: Gremiales | H3: g.caba | I3: prevencion de la ciudad | M3: monotributista | N3: 43536 | O3: =YEAR(NOW())-YEAR(N3) -> 6 | Q3: {=XLOOKUP(C3,fichas_pdf[ap],fichas_pdf[tiene],"no tiene en pdf",0,1)} -> no tiene en pdf
A4: 3 | B4: 31963497 | C4: 444 | D4: 34999032089 | E4: bolivar 191 | F4: caba | G4: Gremiales | H4: g.caba | I4: prevencion de la ciudad | M4: monotributista | N4: 42948 | O4: =YEAR(NOW())-YEAR(N4) -> 8 | Q4: {=XLOOKUP(C4,fichas_pdf[ap],fichas_pdf[tiene],"no tiene en pdf",0,1)} -> 1
A5: 4 | B5: 25379033 | C5: 275 | D5: 34999032089 | E5: bolivar 191 | F5: caba | G5: Gremiales | H5: g.caba | I5: prevencion de la ciudad | M5: monotributista | N5: 42884 | O5: =YEAR(NOW())-YEAR(N5) -> 8 | Q5: {=XLOOKUP(C5,fichas_pdf[ap],fichas_pdf[tiene],"no tiene en pdf",0,1)} -> 1
A6: 5 | B6: 38184089 | C6: 2914 | D6: 34999032089 | E6: bolivar 191 | F6: caba | G6: Gremiales | H6: g.caba | I6: prevencion de la ciudad | M6: monotributista | N6: 45112 | O6: =YEAR(NOW())-YEAR(N6) -> 2 | Q6: {=XLOOKUP(C6,fichas_pdf[ap],fichas_pdf[tiene],"no tiene en pdf",0,1)} -> no tiene en pdf
A7: 6 | B7: 38894668 | C7: 2238 | D7: 34999032089 | E7: bolivar 191 | F7: caba | G7: Gremiales | H7: g.caba | I7: prevencion de la ciudad | M7: monotributista | N7: 45031 | O7: =YEAR(NOW())-YEAR(N7) -> 2 | Q7: {=XLOOKUP(C7,fichas_pdf[ap],fichas_pdf[tiene],"no tiene en pdf",0,1)} -> no tiene en pdf
A8: 7 | B8: 39114453 | C8: 1572 | D8: 34999032089 | E8: bolivar 191 | F8: caba | G8: Gremiales | H8: g.caba | I8: prevencion de la ciudad | M8: monotributista | N8: 43500 | O8: =YEAR(NOW())-YEAR(N8) -> 6 | Q8: {=XLOOKUP(C8,fichas_pdf[ap],fichas_pdf[tiene],"no tiene en pdf",0,1)} -> no tiene en pdf
A9: 8 | B9: 26678242 | C9: 270 | D9: 34999032089 | E9: bolivar 191 | F9: caba | G9: Gremiales | H9: g.caba | I9: prevencion de la ciudad | M9: planta transitoria | N9: 42887 | O9: =YEAR(NOW())-YEAR(N9) -> 8 | Q9: {=XLOOKUP(C9,fichas_pdf[ap],fichas_pdf[tiene],"no tiene en pdf",0,1)} -> no tiene en pdf
A10: 9 | B10: 42012262 | C10: 2166 | D10: 34999032089 | E10: bolivar 191 | F10: caba | G10: Gremiales | H10: g.caba | I10: prevencion de la ciudad | M10: monotributista | N10: 0 | O10: =YEAR(NOW())-YEAR(N10) -> 126 | Q10: {=XLOOKUP(C10,fichas_pdf[ap],fichas_pdf[tiene],"no tiene en pdf",0,1)} -> no tiene en pdf
A11: 10 | B11: 33155103 | C11: 1023 | D11: 34999032089 | E11: bolivar 191 | F11: caba | G11: Gremiales | H11: g.caba | I11: prevencion de la ciudad | M11: monotributista | N11: 42948 | O11: =YEAR(NOW())-YEAR(N11) -> 8 | Q11: {=XLOOKUP(C11,fichas_pdf[ap],fichas_pdf[tiene],"no tiene en pdf",0,1)} -> 1
A12: 11 | B12: 35538835 | C12: 1025 | D12: 34999032089 | E12: bolivar 191 | F12: caba | G12: Gremiales | H12: g.caba | I12: prevencion de la ciudad | M12: monotributista | N12: 0 | O12: =YEAR(NOW())-YEAR(N12) -> 126 | Q12: {=XLOOKUP(C12,fichas_pdf[ap],fichas_pdf[tiene],"no tiene en pdf",0,1)} -> 1
A13: 12 | B13: 93996095 | C13: 754 | D13: 34999032089 | E13: bolivar 191 | F13: caba | G13: Gremiales | H13: g.caba | I13: prevencion de la ciudad | M13: monotributista | N13: 42948 | O13: =YEAR(NOW())-YEAR(N13) -> 8 | Q13: {=XLOOKUP(C13,fichas_pdf[ap],fichas_pdf[tiene],"no tiene en pdf",0,1)} -> 1
A14: 13 | B14: 94842492 | C14: 527 | D14: 34999032089 | E14: bolivar 191 | F14: caba | G14: Gremiales | H14: g.caba | I14: prevencion de la ciudad | M14: monotributista | N14: 0 | O14: =YEAR(NOW())-YEAR(N14) -> 126 | Q14: {=XLOOKUP(C14,fichas_pdf[ap],fichas_pdf[tiene],"no tiene en pdf",0,1)} -> 1
... A35: 36 | B35: 29064893 | C35: 1677 | D35: 34999032089 | E35: bolivar 191 | F35: caba | G35: Gremiales | H35: g.caba | I35: prevencion de la ciudad | M35: monotributista | N35: 43617 | O35: =YEAR(NOW())-YEAR(N35) -> 6 | Q35: {=XLOOKUP(C35,fichas_pdf[ap],fichas_pdf[tiene],"no tiene en pdf",0,1)} -> 1
A36: 37 | B36: 39294750 | C36: 211 | D36: 34999032089 | H36: g.caba | I36: prevencion de la ciudad | M36: Planta Permanente | N36: 42795 | O36: =YEAR(NOW())-YEAR(N36) -> 8 | Q36: {=XLOOKUP(C36,fichas_pdf[ap],fichas_pdf[tiene],"no tiene en pdf",0,1)} -> no tiene en pdf
A37: 38 | B37: 37388128 | C37: 1112 | D37: 34999032089 | H37: g.caba | I37: prevencion de la ciudad | M37: Monotributista | N37: 42948 | O37: =YEAR(NOW())-YEAR(N37) -> 8 | Q37: {=XLOOKUP(C37,fichas_pdf[ap],fichas_pdf[tiene],"no tiene en pdf",0,1)} -> no tiene en pdf
A38: 39 | B38: 36848082 | C38: 1679 | D38: 34999032089 | H38: g.caba | I38: prevencion de la ciudad | M38: Monotributista | N38: 41598 | O38: =YEAR(NOW())-YEAR(N38) -> 12 | P38: 1 | Q38: {=XLOOKUP(C38,fichas_pdf[ap],fichas_pdf[tiene],"no tiene en pdf",0,1)} -> no tiene en pdf
A39: 40 | B39: 31403780 | C39: 729 | D39: 34999032089 | H39: g.caba | I39: prevencion de la ciudad | M39: Monotributista | N39: 42948 | O39: =YEAR(NOW())-YEAR(N39) -> 8 | Q39: {=XLOOKUP(C39,fichas_pdf[ap],fichas_pdf[tiene],"no tiene en pdf",0,1)} -> no tiene en pdf
A40: 41 | B40: 41917769 | C40: 1923 | D40: 34999032089 | H40: g.caba | I40: prevencion de la ciudad | M40: Monotributista | N40: 44713 | O40: =YEAR(NOW())-YEAR(N40) -> 3 | Q40: {=XLOOKUP(C40,fichas_pdf[ap],fichas_pdf[tiene],"no tiene en pdf",0,1)} -> 1
A41: 42 | B41: 22826482 | C41: 130 | D41: 34999032089 | H41: g.caba | I41: prevencion de la ciudad | M41: Planta Permanente | N41: 42675 | O41: =YEAR(NOW())-YEAR(N41) -> 9 | Q41: {=XLOOKUP(C41,fichas_pdf[ap],fichas_pdf[tiene],"no tiene en pdf",0,1)} -> no tiene en pdf
A42: 43 | B42: 37060301 | C42: 2883 | D42: 34999032089 | H42: g.caba | I42: prevencion de la ciudad | M42: Monotributista | O42: =YEAR(NOW())-YEAR(N42) -> 126 | Q42: {=XLOOKUP(C42,fichas_pdf[ap],fichas_pdf[tiene],"no tiene en pdf",0,1)} -> 1
A43: 44 | B43: 21130792 | C43: 1579 | D43: 34999032089 | H43: g.caba | I43: prevencion de la ciudad | M43: Monotributista | N43: 43497 | O43: =YEAR(NOW())-YEAR(N43) -> 6 | Q43: {=XLOOKUP(C43,fichas_pdf[ap],fichas_pdf[tiene],"no tiene en pdf",0,1)} -> no tiene en pdf
A44: 45 | B44: 24033237 | C44: 303 | D44: 34999032089 | H44: g.caba | I44: prevencion de la ciudad | M44: Planta Transitoria | N44: 42983 | O44: =YEAR(NOW())-YEAR(N44) -> 8 | Q44: {=XLOOKUP(C44,fichas_pdf[ap],fichas_pdf[tiene],"no tiene en pdf",0,1)} -> no tiene en pdf
A45: 46 | B45: 22656778 | C45: 1116 | D45: 34999032089 | H45: g.caba | I45: prevencion de la ciudad | M45: Monotributista | N45: 42954 | O45: =YEAR(NOW())-YEAR(N45) -> 8 | Q45: {=XLOOKUP(C45,fichas_pdf[ap],fichas_pdf[tiene],"no tiene en pdf",0,1)} -> 1
A46: 47 | B46: 35353668 | C46: 1640 | D46: 34999032089 | H46: g.caba | I46: prevencion de la ciudad | M46: Monotributista | N46: 43525 | O46: =YEAR(NOW())-YEAR(N46) -> 6 | P46: 1 | Q46: {=XLOOKUP(C46,fichas_pdf[ap],fichas_pdf[tiene],"no tiene en pdf",0,1)} -> no tiene en pdf
A47: 48 | B47: 22982124 | C47: 1849 | D47: 34999032089 | H47: g.caba | I47: prevencion de la ciudad | M47: Monotributista | N47: 44319 | O47: =YEAR(NOW())-YEAR(N47) -> 4 | Q47: {=XLOOKUP(C47,fichas_pdf[ap],fichas_pdf[tiene],"no tiene en pdf",0,1)} -> no tiene en pdf
A48: 50 | B48: 21981832 | C48: 2447 | D48: 34999032089 | H48: g.caba | I48: prevencion de la ciudad | M48: Monotributista | O48: =YEAR(NOW())-YEAR(N48) -> 126 | Q48: {=XLOOKUP(C48,fichas_pdf[ap],fichas_pdf[tiene],"no tiene en pdf",0,1)} -> no tiene en pdf
A49: 51 | B49: 41639943 | C49: 2449 | D49: 34999032089 | H49: g.caba | I49: prevencion de la ciudad | M49: Monotributista | O49: =YEAR(NOW())-YEAR(N49) -> 126 | Q49: {=XLOOKUP(C49,fichas_pdf[ap],fichas_pdf[tiene],"no tiene en pdf",0,1)} -> no tiene en pdf
A50: 52 | B50: 32404463 | D50: 34999032089 | H50: g.caba | I50: prevencion de la ciudad | M50: Monotributista | O50: =YEAR(NOW())-YEAR(N50) -> 126 | Q50: {=XLOOKUP(C50,fichas_pdf[ap],fichas_pdf[tiene],"no tiene en pdf",0,1)} -> no tiene en pdf
A51: 53 | B51: 36786519 | C51: 2776 | D51: 34999032089 | H51: g.caba | I51: prevencion de la ciudad | M51: Monotributista | O51: =YEAR(NOW())-YEAR(N51) -> 126 | Q51: {=XLOOKUP(C51,fichas_pdf[ap],fichas_pdf[tiene],"no tiene en pdf",0,1)} -> no tiene en pdf
A52: 54 | B52: 37036332 | C52: 1644 | D52: 34999032089 | H52: g.caba | I52: prevencion de la ciudad | M52: Monotributista | N52: 43525 | O52: =YEAR(NOW())-YEAR(N52) -> 6 | Q52: {=XLOOKUP(C52,fichas_pdf[ap],fichas_pdf[tiene],"no tiene en pdf",0,1)} -> 1
A53: 55 | B53: 44364634 | C53: 2463 | D53: 34999032089 | H53: g.caba | I53: prevencion de la ciudad | M53: Monotributista | O53: =YEAR(NOW())-YEAR(N53) -> 126 | Q53: {=XLOOKUP(C53,fichas_pdf[ap],fichas_pdf[tiene],"no tiene en pdf",0,1)} -> no tiene en pdf
A54: 56 | B54: 41263312 | C54: 2267 | D54: 34999032089 | H54: g.caba | I54: prevencion de la ciudad | M54: Monotributista | O54: =YEAR(NOW())-YEAR(N54) -> 126 | Q54: {=XLOOKUP(C54,fichas_pdf[ap],fichas_pdf[tiene],"no tiene en pdf",0,1)} -> 1
A55: 57 | B55: 42586370 | C55: 1645 | D55: 34999032089 | H55: g.caba | I55: prevencion de la ciudad | M55: Monotributista | N55: 43556 | O55: =YEAR(NOW())-YEAR(N55) -> 6 | Q55: {=XLOOKUP(C55,fichas_pdf[ap],fichas_pdf[tiene],"no tiene en pdf",0,1)} -> 1
A56: 58 | B56: 40748856 | C56: 1241 | D56: 34999032089 | H56: g.caba | I56: prevencion de la ciudad | M56: Monotributista | N56: 43110 | O56: =YEAR(NOW())-YEAR(N56) -> 7 | P56: 1 | Q56: {=XLOOKUP(C56,fichas_pdf[ap],fichas_pdf[tiene],"no tiene en pdf",0,1)} -> no tiene en pdf
A57: 59 | B57: 18205196 | C57: 111 | D57: 34999032089 | H57: g.caba | I57: prevencion de la ciudad | M57: Planta Permanente | N57: 41122 | O57: =YEAR(NOW())-YEAR(N57) -> 13 | P57: 1 | Q57: {=XLOOKUP(C57,fichas_pdf[ap],fichas_pdf[tiene],"no tiene en pdf",0,1)} -> no tiene en pdf
A58: 60 | B58: 34871654 | C58: 2785 | D58: 34999032089 | H58: g.caba | I58: prevencion de la ciudad | M58: Monotributista | N58: 45111 | O58: =YEAR(NOW())-YEAR(N58) -> 2 | Q58: {=XLOOKUP(C58,fichas_pdf[ap],fichas_pdf[tiene],"no tiene en pdf",0,1)} -> no tiene en pdf
A59: 61 | B59: 39275500 | C59: 3150 | D59: 34999032089 | H59: g.caba | I59: prevencion de la ciudad | M59: Monotributista | O59: =YEAR(NOW())-YEAR(N59) -> 126 | Q59: {=XLOOKUP(C59,fichas_pdf[ap],fichas_pdf[tiene],"no tiene en pdf",0,1)} -> no tiene en pdf
A60: 62 | B60: 40133136 | C60: 2275 | D60: 34999032089 | H60: g.caba | I60: prevencion de la ciudad | M60: Monotributista | N60: 45291 | O60: =YEAR(NOW())-YEAR(N60) -> 2 | P60: 0 | Q60: {=XLOOKUP(C60,fichas_pdf[ap],fichas_pdf[tiene],"no tiene en pdf",0,1)} -> no tiene en pdf
...

Sheet fichas_pdf
A1: ap | B1: apellido | C1: nombre | D1: tiene
A2: 275 | B2: Amaya | C2: MarielaCecilia | D2: 1
A3: 444 | B3: Aranda | C3: Natalia | D3: 1
A4: 527 | B4: Olayiña | C4: Laly | D4: 1
A5: 543 | B5: Rodriguez | C5: Paola | D5: 1
A6: 560 | B6: FerroRodriguez | C6: MariaElena | D6: 1
A7: 754 | B7: FelipeLima | C7: Aidee | D7: 1
A8: 769 | B8: Gonzalez | C8: Agostina | D8: 1
A9: 773 | B9: Grillo | C9: Viviana | D9: 1
A10: 909 | B10: GutierrezQuispe | C10: Grisela | D10: 1
A11: 941 | B11: Martinez | C11: Raquel | D11: 1
A12: 1004 | B12: Quiroga | C12: Claudio | D12: 1
A13: 1023 | B13: Romero | C13: Irina | D13: 1
... A91: 2177 | B91: Espinoza | C91: Camila | D91: 1
A92: XXXX | B92: FigueroaNarvaez | C92: Brigitte | D92: 1
A93: XXXX | B93: Martinez | C93: Debora | D93: 1
A94: 1124 | B94: Palacio | C94: Gustavo | D94: 1
A95: XXXX | B95: Quevedo | C95: Camila | D95: 1
A96: XXXX | B96: Raed | C96: Walter | D96: 1

Sheet Hoja 11
A1: Apellido/s nombre/s | B1: AP | C1: Teléfono de contacto | D1: Cuando ingreso a prevención | E1: ¿En que comuna esta tu sendero? | F1: Apellido/s y Nombre/s hijo/a 1 | G1: D.n.i hijo/a 1 | H1: Fecha nacimiento hijo/a 1 | I1: Apellido/s y Nombre/s hijo/a 2 | J1: D.n.i hijo/a 2 | K1: Fecha nacimiento hijo/a 2 | L1: Apellido/s y Nombre/s hijo/a 3 | M1: D.n.i hijo/a 3 | N1: Fecha nacimiento hijo/a 3 | O1: Apellido/s y Nombre/s hijo/a 4 | P1: D.n.i hijo/a 4 | Q1: Fecha nacimiento hijo/a 4 | R1: Apellido/s y Nombre/s hijo/a 5 | S1: D.n.i hijo/a 5 | T1: Fecha nacimiento hijo/a 5 | U1: Apellido/s y Nombre/s hijo/a 6 | V1: D.n.i hijo/a 6 | W1: Fecha nacimiento hijo/a 6 | X1: Apellido/s y Nombre/s hijo/a 7 | Y1: D.n.i hijo/a 7 | Z1: Fecha nacimiento hijo/a 7
A2: Quispe Coronado José Luis | B2: 180 | C2: 1160531098 | D2: 42655 | E2: Comuna. 8 | F2: Quispe Rivadeneyra Matilda Aylen | G2: 55389451 | H2: 42398 | I2: . | J2: .
A3: Amaya mariela | B3: 275 | C3: 1126921416 | D3: 42884 | E3: Bolivar | F3: Victoria otero | G3: 53171566 | H3: 41358
A4: Serrano natalia | B4: 413 | C4: 1124773534 | D4: 42884 | E4: 12 | F4: Morano Sofia | G4: 50289508 | H4: 40276
A5: Aranda Natalia | B5: 444 | C5: 1156294264 | D5: 42917 | E5: Comuna 8 sendero jumbo | F5: Falcon Sofia | G5: 49002653 | H5: 39879 | I5: Falcon Santino | J5: 54185111 | K5: 41872
A6: Obredor romina natalia | B6: 526 | C6: 1136983612 | D6: 42921 | E6: 8 | F6: Bautista zuriel muñoz obredor | G6: 49701830 | H6: 40030 | I6: Ciro heber muñoz obredor | J6: 54100632 | K6: 41815
A7: Paola Rodriguez | B7: 543 | C7: 1130404995 | D7: 42919 | E7: 5 | F7: Rodriguez Etter , Morena Ariana | G7: 50156592 | H7: 40234
A8: Crespin Daniela | B8: 740 | C8: 1124302371 | D8: 42950 | E8: 8 | F8: Álvarez Malena | G8: 50501211 | H8: 40433
A9: Felipe lima Aidee Deysi | B9: 754 | C9: 1128666648 | D9: 42954 | E9: 14 | F9: Flores Daiara celeste | G9: 49002705 | H9: 39910 | I9: Flores sheila azul | J9: 50289552 | K9: 40537 | L9: Flores Camilo Ian | M9: 56385774 | N9: 42893
A10: González Agostina | B10: 769 | C10: 1141633096 | D10: 42948 | E10: 1 | F10: Martinez, Eren Lionel | G10: 54792550 | H10: 42108 | I10: Martinez, Gala Isabella | J10: 58026189 | K10: 43766 | L10: Martinez, Noah Federico | M10: 58873165 | N10: 44361
A11: Gutierrez Quispe Grisela | B11: 909 | C11: 1124936411 | D11: 42954 | E11: 7 | F11: Lizarraga Gutierrez Adriana Grisel | G11: 95189739 | H11: 46148 | I11: Lizarraga Gutierrez Mariana Dail | J11: 95189738 | K11: 39336 | L11: Lizarraga Gutierrez Leonardo Jhoel | M11: 95189737 | N11: 40095 | O11: Lizarraga Gutierrez Gonzalo Marino | P11: 53649865 | Q11: 41651
A12: Pineda Mongelos Sindy Kathiana | B12: 996 | C12: 1138863933 | D12: 42951 | E12: Comuna15 | F12: Gómez Pineda Sofía Ailén | G12: 48463113 | H12: 39475 | I12: Gómez Pineda Selene Antonella | J12: 50437489 | K12: 40381
A13: Romero irina | B13: 1023 | C13: 1165037377 | D13: 42948 | E13: Comuna 7 | F13: Franco romero uma | G13: 49008586 | H13: 39710 | I13: Gonzalez lionel | K13: 45435
A14: Uriarte Romina Maria Lujan | B14: 1065 | C14: 1156952628 | D14: 42948 | E14: 6 | F14: Romero Bautista Tomas | G14: 50288520 | H14: 40303
A15: Sinchicay, Nelida | B15: 1142 | C15: 1130700402 | D15: 42954 | E15: Comuna 8 | F15: Jacquet Sinchicay, Alejo | G15: 54699167 | H15: 42117
A16: Claudio Servando Salazar | B16: 1234 | C16: 1161708518 | D16: 43164 | E16: 1 | F16: Briana Naomi Salazar rios | G16: 59738820 | H16: 45030
A17: Linos Dolores del Carmen | B17: 1536 | C17: 1166665806 | D17: 43405 | E17: Comuna 3 | F17: Gimenez Gonzalo Lionel | G17: 50678363 | H17: 40455 | I17: Gimenez Valentina | J17: 52656821 | K17: 41121
A18: Portillo Lucrecia isabel | B18: 1597 | C18: 1168039045 | D18: 43497 | E18: 1 | F18: Mara Valentina Cruz | G18: 70.264.168 | H18: 45336
A19: Ferrari Brenda | B19: 1644 | C19: 1139323687 | D19: 43525 | E19: 8 | F19: Pérez Ferrari Renata | G19: 53653388 | H19: 41641
A20: Fernando Figueroa | B20: 1645 | C20: 1125475896 | D20: 43537 | E20: 10 | F20: Isaac Emmanuel Figueroa | G20: 58295780 | H20: 43946
A21: Martin Nicole | B21: 1657 | C21: 1124014213 | D21: 43525 | E21: 11 | F21: Olivia Renata Gomez Martin | G21: 55761712 | H21: 42604
A22: Siles Romina Leticia | B22: 1665 | C22: 1168069316 | D22: 29196 | E22: Comuna 9 | F22: --------' | G22: -----------' | I22: ------- | J22: --------
A23: Iglesias Jaeger Sofía Tamara | B23: 1683 | C23: 1121759987 | D23: 43586 | E23: 9 | F23: Olas Benjamín Román | G23: 51267277 | H23: 40728
A24: Machado Sotomayor Sandra | B24: 1736 | C24: 1162777192 | D24: 43678 | E24: C1 | F24: Dillon Liam | G24: 55167991 | H24: 42354
A25: Benítez Lucas | B25: 1753 | C25: 1169603036 | D25: 43754 | E25: 8 | F25: Benítez Veiga Zeus Leónidas | G25: 54299563 | H25: 41910 | I25: Benítez Veiga Zoe Leila | J25: 57477622 | K25: 43505
A26: Navarro Elizabeth | B26: 1768 | C26: 1122973101 | D26: 43727 | E26: 9 | F26: Touze Navarro Thiago Uriel | G26: 47867049 | H26: 39172 | I26: Figueredo Navarro Valentino Gael | J26: 59553145 | K26: 45165
A27: Silva Luciana Belen | B27: 1777 | C27: 1137587184 | D27: 43748 | E27: 8 | F27: Ferrante Silva Tiziano Gabriel | G27: 54631191 | H27: 42067
A28: López Julieta | B28: 1873 | C28: 1156201540 | D28: 44319 | E28: 3 | F28: Benítez Bruno Agustín | G28: 54055608 | H28: 41808 | I28: Benítez López Leonardo Joaquín | J28: 56052831 | K28: 42763
A29: Benítez miriagly | B29: 1919 | C29: 1138122802 | D29: 44666 | E29: 8 | F29: Andrés Eduardo Luis Benitez | G29: 95765873 | H29: 38763
A30: Dugour Cecilia Paola | B30: 1931 | C30: 1141697938 | D30: 44683 | E30: 6 | F30: Dugour Santiago | G30: 47170109
A31: Perez fernanda | B31: 1953 | C31: 1126573366 | D31: 44703 | E31: Balvanera | F31: Roldan perez matias leonel | G31: 52768578 | H31: 41242
A32: Proz Magali Nahir | B32: 1970 | C32: 1138958145 | D32: 44490 | E32: Comuna 3 | F32: Gómez Proz Zoe Morella | G32: 54352952 | H32: 41936
A33: Nieva, Alcira del Valle | B33: 1978 | C33: 1557802702 | D33: 44809 | E33: Comuna 1 | F33: Delgadillo Nieva, Luciano Sandro | G33: 51576533 | H33: 40903
A34: López Lilian | B34: 1989 | C34: 1151065312 | D34: 44743 | E34: 5 | F34: Gonzalez Lopez Dafne Xiomara | G34: 54519818 | H34: 42015 | I34: Gonzalez López Jana Naylen | J34: 55885848 | K34: 42680
A35: Araujo Jesica Mabel | B35: 2005 | C35: 1156602116 | D35: 44900 | E35: Comuna 8 | F35: Glavovich Zamira Agostina | G35: 55990157 | H35: 42745
A36: Villegas Oscar | B36: 2043 | C36: 1127563862 | D36: 44872 | E36: Comuna 1 | F36: Villegas Centurión Aarón Zaid | G36: 55696264 | H36: 42576 | I36: Villegas Centurión Martina Antonella | J36: 56992871 | K36: 43170
A37: Acosta Gladys Natalia | B37: 2096 | C37: 1153412891 | D37: 45020 | E37: 1 | F37: Martinez Alma Francesca | G37: 57515739 | H37: 43478
A38: González Paola yanet | B38: 2124 | C38: 1126259891 | D38: 45028 | E38: Comuna 13 | F38: Abregu Lionel benjamin | G38: 56197666 | H38: 43032 | I38: Abregu emily Antonella | J38: 70487044 | K38: 45672
A39: Morales llanos camila marisol | B39: 2136 | C39: 1151415767 | D39: 45021 | E39: 7 | F39: Rodríguez Morales Valentina priscila | G39: 70360614 | H39: 45511 | I39: Rodríguez Morales Julieta Luciana | J39: 70360613 | K39: 45511
A40: Noseda María Belén | B40: 2137 | C40: 1165018528 | D40: 44991 | E40: Comuna 12 | F40: Comerci Helena | G40: 58.492.812 | H40: 43969
...

Sheet aux_BD_Delegados
A1: id: | B1: clave_foranea: | C1: Inicio mandato | D1: En Actividad | E1: Años mandato | F1: Observaciones
A2: 1 | B2: 25379033 | C2: 45078 | D2: 1 | E2: =IF(D2 = 1,YEAR(NOW())-YEAR(C2),"fin mandato") -> 2
A3: 2 | B3: 95102089 | C3: 45079 | D3: 1 | E3: =IF(D3 = 1,YEAR(NOW())-YEAR(C3),"fin mandato") -> 2
A4: 3 | B4: 29064893 | C4: 45080 | D4: 1 | E4: =IF(D4 = 1,YEAR(NOW())-YEAR(C4),"fin mandato") -> 2
A5: 4 | B5: 37388128 | C5: 45081 | D5: 1 | E5: =IF(D5 = 1,YEAR(NOW())-YEAR(C5),"fin mandato") -> 2
A6: 5 | B6: 22826482 | C6: 45082 | D6: 1 | E6: =IF(D6 = 1,YEAR(NOW())-YEAR(C6),"fin mandato") -> 2
A7: 6 | B7: 29319005 | C7: 45083 | D7: 1 | E7: =IF(D7 = 1,YEAR(NOW())-YEAR(C7),"fin mandato") -> 2
A8: 7 | B8: 31703988 | C8: 45084 | D8: 1 | E8: =IF(D8 = 1,YEAR(NOW())-YEAR(C8),"fin mandato") -> 2 | F8: comuna
A9: 8 | B9: 30455729 | C9: 45085 | D9: 1 | E9: =IF(D9 = 1,YEAR(NOW())-YEAR(C9),"fin mandato") -> 2
A10: 9 | B10: 34583817 | C10: 45086 | D10: 1 | E10: =IF(D10 = 1,YEAR(NOW())-YEAR(C10),"fin mandato") -> 2
A11: 10 | B11: 40239878 | C11: 45087 | D11: 1 | E11: =IF(D11 = 1,YEAR(NOW())-YEAR(C11),"fin mandato") -> 2
A12: 11 | B12: 30465419 | C12: 45088 | D12: 1 | E12: =IF(D12 = 1,YEAR(NOW())-YEAR(C12),"fin mandato") -> 2
A13: 12 | B13: 37099313 | C13: 45089 | D13: 1 | E13: =IF(D13 = 1,YEAR(NOW())-YEAR(C13),"fin mandato") -> 2
A14: 13 | B14: 21365112 | C14: 45090 | D14: 1 | E14: =IF(D14 = 1,YEAR(NOW())-YEAR(C14),"fin mandato") -> 2
A15: 14 | B15: 31164406 | C15: 45091 | D15: 1 | E15: =IF(D15 = 1,YEAR(NOW())-YEAR(C15),"fin mandato") -> 2
A16: 15 | B16: 33250656 | C16: 45092 | D16: 1 | E16: =IF(D16 = 1,YEAR(NOW())-YEAR(C16),"fin mandato") -> 2
A17: 16 | B17: 24033237 | C17: 45093 | D17: 1 | E17: =IF(D17 = 1,YEAR(NOW())-YEAR(C17),"fin mandato") -> 2

Sheet conyuges
A1: id: | B1: Clave_foranea: | C1: Nombre y Apellido: | D1: D.n.i: | E1: Fecha de Nacimiento:
A2: 1 | B2: 21726330
A3: 2 | B3: 32436304
A4: 3 | B4: 31963497
A5: 4 | B5: 25379033 | C5: otero gustavo | D5: 13801311 | E5: 21972
A6: 5 | B6: 38184089
A7: 6 | B7: 38894668
A8: 7 | B8: 39114453
A9: 8 | B9: 26678242
A10: 9 | B10: 42012262
A11: 10 | B11: 33155103
A12: 11 | B12: 35538835
A13: 12 | B13: 93996095
A14: 13 | B14: 94842492
A15: 14 | B15: 95102089 | C15: julio cesar maidana | D15: 18473969 | E15: 24764
A16: 15 | B16: 95189729
A17: 16 | B17: 20009014 | E17: 0
A18: 17 | B18: 29635937 | C18: jorge botenstein | D18: 17107105 | E18: 23620
A19: 18 | B19: 39471585 | C19: almada roque noberto | D19: 13965388 | E19: 21802
A20: 19 | B20: 43817038
A21: 20 | B21: 44486458
A22: 21 | B22: 36685920
A23: 22 | B23: 25060598
A24: 23 | B24: 31896263
A25: 24 | B25: 32554313
A26: 25 | B26: 40241420 | C26: rodrigo galeano | D26: 36359917 | E26: 33414
A27: 26 | B27: 33905319
A28: 27 | B28: 31302984
A29: 28 | B29: 34423850
A30: 29 | B30: 32616368
A31: 30 | B31: 42498064
A32: 31 | B32: 43241630
A33: 32 | B33: 30440348
A34: 33 | B34: 30211914 | C34: cristian trapani | D34: 33719240 | E34: 32262
A35: 34 | B35: 40873767 | C35: ruben baez | D35: 2889177 | E35: 30861
A36: 35 | B36: 94075255 | C36: hector antonio velazavez | D36: 92996350 | E36: 28789
A37: 36 | B37: 29064893 | C37: sandra navarro | D37: no dato | E37: 30010
A38: 37 | B38: 39294750
A39: 38 | B39: 37388128
A40: 39 | B40: 36848082
...

Sheet padron_prevecion
A1: comentarios VERO | B1: comentarios VERO1 | C1: id | D1: Relacion de Dependencia | E1: Delegados | F1: Afiliados: | G1: AP | H1: Ingreso a Prevención | I1: Años de actividad: | J1: DNI | K1: Fecha de Nacimiento | L1: Menores a Cargo | M1: kit-1 | N1: kit-2 | O1: kit-3 | P1: kit-4 | Q1: cantidad de kits | R1: Celular Particular | S1: Email | T1: esta_grupo_upcn | U1: renucio | V1: tiene_ficha_pdf
C2: =datos_personales[id:] -> 21726330 | D2: {=XLOOKUP(C2,datos_laborales[clave_foranea],datos_laborales[Relacion de Dependencia],"dato no encontrado",0,1)} -> planta permanente | E2: {=XLOOKUP(C2,datos_delegados[clave_foranea:],datos_delegados[En Actividad]," ",0,1)} | F2: {=CONCATENATE(XLOOKUP(C2,datos_personales[id:],datos_personales[Apellido:],"no dato",0,1),", ",XLOOKUP(C2,datos_personales[id:],datos_personales[Nombre],"no dato",0,1))} -> battafarano, amelia andrea | G2: {=XLOOKUP(C2,datos_laborales[clave_foranea],datos_laborales[N° De Legajo],"no dato",0,1)} -> 127 | H2: {=XLOOKUP(C2,datos_laborales[clave_foranea], datos_laborales[Inicio Actividad:],"no dato",0,1)} -> 42767 | I2: {=XLOOKUP(C2,datos_laborales[clave_foranea],datos_laborales[Años en Actividad:],"no dato",0,1)} -> 8 | J2: {=XLOOKUP(C2,datos_personales[id:],datos_personales[D.n.i:],"no dato",0,1)} -> 21726330 | K2: {=XLOOKUP(C2,datos_personales[id:],datos_personales[Fecha Nacimiento:],"no dato",0,1)} -> 25771 | L2: =COUNTIF(hijos!B:B,C2) -> 1 | M2: =COUNTIFS(hijos!B:B,C2,hijos!I:I,1) -> 0 | N2: =COUNTIFS(hijos!B:B,C2,hijos!J:J,1) -> 0 | O2: =COUNTIFS(hijos!B:B,C2,hijos!K:K,1) -> 0 | P2: =COUNTIFS(hijos!B:B,C2,hijos!L:L,1) -> 1 | Q2: =SUM(M2:P2) -> 1 | R2: {=XLOOKUP(C2,datos_personales[id:],datos_personales[Tel. Contacto:],"no dato",0,1)} -> 1144271929 | S2: {=XLOOKUP(C2,datos_personales[id:],datos_personales[E-Mail:],"no dato",0,1)} -> andrius_1970@hotmail.com | T2: {=XLOOKUP(R2,telefonos_afiliados[numeros_loys],telefonos_afiliados[esta],"no esta",0,1)} -> no esta | U2: {=XLOOKUP(C2,datos_personales[id:],datos_laborales[renuncio],"no dato",0,1)} -> #N/A | V2: {=XLOOKUP(C2,datos_laborales[clave_foranea],datos_laborales[tiene_ficha_pdf],"no tiene ficha pdf",0,1)} -> no tiene en pdf
C3: =datos_personales[id:] -> 32436304 | D3: {=XLOOKUP(C3,datos_laborales[clave_foranea],datos_laborales[Relacion de Dependencia],"dato no encontrado",0,1)} -> monotributista | E3: {=XLOOKUP(C3,datos_delegados[clave_foranea:],datos_delegados[En Actividad]," ",0,1)} | F3: {=CONCATENATE(XLOOKUP(C3,datos_personales[id:],datos_personales[Apellido:],"no dato",0,1),", ",XLOOKUP(C3,datos_personales[id:],datos_personales[Nombre],"no dato",0,1))} -> arroyo, elizabeth beatriz | G3: {=XLOOKUP(C3,datos_laborales[clave_foranea],datos_laborales[N° De Legajo],"no dato",0,1)} -> 1575 | H3: {=XLOOKUP(C3,datos_laborales[clave_foranea], datos_laborales[Inicio Actividad:],"no dato",0,1)} -> 43536 | I3: {=XLOOKUP(C3,datos_laborales[clave_foranea],datos_laborales[Años en Actividad:],"no dato",0,1)} -> 6 | J3: {=XLOOKUP(C3,datos_personales[id:],datos_personales[D.n.i:],"no dato",0,1)} -> 32436304 | K3: {=XLOOKUP(C3,datos_personales[id:],datos_personales[Fecha Nacimiento:],"no dato",0,1)} -> 31527 | L3: =COUNTIF(hijos!B:B,C3) -> 0 | M3: =COUNTIFS(hijos!B:B,C3,hijos!I:I,1) -> 0 | N3: =COUNTIFS(hijos!B:B,C3,hijos!J:J,1) -> 0 | O3: =COUNTIFS(hijos!B:B,C3,hijos!K:K,1) -> 0 | P3: =COUNTIFS(hijos!B:B,C3,hijos!L:L,1) -> 0 | Q3: =SUM(M3:P3) -> 0 | R3: {=XLOOKUP(C3,datos_personales[id:],datos_personales[Tel. Contacto:],"no dato",0,1)} | S3: {=XLOOKUP(C3,datos_personales[id:],datos_personales[E-Mail:],"no dato",0,1)} -> elizabeth_arroyo25@hotmail.com | T3: {=XLOOKUP(R3,telefonos_afiliados[numeros_loys],telefonos_afiliados[esta],"no esta",0,1)} -> no esta | U3: {=XLOOKUP(C3,datos_personales[id:],datos_laborales[renuncio],"no dato",0,1)} -> #N/A | V3: {=XLOOKUP(C3,datos_laborales[clave_foranea],datos_laborales[tiene_ficha_pdf],"no tiene ficha pdf",0,1)} -> no tiene en pdf
C4: =datos_personales[id:] -> 31963497 | D4: {=XLOOKUP(C4,datos_laborales[clave_foranea],datos_laborales[Relacion de Dependencia],"dato no encontrado",0,1)} -> monotributista | E4: {=XLOOKUP(C4,datos_delegados[clave_foranea:],datos_delegados[En Actividad]," ",0,1)} | F4: {=CONCATENATE(XLOOKUP(C4,datos_personales[id:],datos_personales[Apellido:],"no dato",0,1),", ",XLOOKUP(C4,datos_personales[id:],datos_personales[Nombre],"no dato",0,1))} -> aranda, natalia veronica | G4: {=XLOOKUP(C4,datos_laborales[clave_foranea],datos_laborales[N° De Legajo],"no dato",0,1)} -> 444 | H4: {=XLOOKUP(C4,datos_laborales[clave_foranea], datos_laborales[Inicio Actividad:],"no dato",0,1)} -> 42948 | I4: {=XLOOKUP(C4,datos_laborales[clave_foranea],datos_laborales[Años en Actividad:],"no dato",0,1)} -> 8 | J4: {=XLOOKUP(C4,datos_personales[id:],datos_personales[D.n.i:],"no dato",0,1)} -> 31963497 | K4: {=XLOOKUP(C4,datos_personales[id:],datos_personales[Fecha Nacimiento:],"no dato",0,1)} -> 0 | L4: =COUNTIF(hijos!B:B,C4) -> 2 | M4: =COUNTIFS(hijos!B:B,C4,hijos!I:I,1) -> 0 | N4: =COUNTIFS(hijos!B:B,C4,hijos!J:J,1) -> 0 | O4: =COUNTIFS(hijos!B:B,C4,hijos!K:K,1) -> 1 | P4: =COUNTIFS(hijos!B:B,C4,hijos!L:L,1) -> 1 | Q4: =SUM(M4:P4) -> 2 | R4: {=XLOOKUP(C4,datos_personales[id:],datos_personales[Tel. Contacto:],"no dato",0,1)} -> 1156294264 | S4: {=XLOOKUP(C4,datos_personales[id:],datos_personales[E-Mail:],"no dato",0,1)} -> aranda_natalia@hotmail.com.ar | T4: {=XLOOKUP(R4,telefonos_afiliados[numeros_loys],telefonos_afiliados[esta],"no esta",0,1)} -> 1 | U4: {=XLOOKUP(C4,datos_laborales[id:],datos_laborales[renuncio],"no dato",0,1)} -> no dato | V4: {=XLOOKUP(C4,datos_laborales[clave_foranea],datos_laborales[tiene_ficha_pdf],"no tiene ficha pdf",0,1)} -> 1
C5: =datos_personales[id:] -> 25379033 | D5: {=XLOOKUP(C5,datos_laborales[clave_foranea],datos_laborales[Relacion de Dependencia],"dato no encontrado",0,1)} -> monotributista | E5: {=XLOOKUP(C5,datos_delegados[clave_foranea:],datos_delegados[En Actividad]," ",0,1)} -> 1 | F5: {=CONCATENATE(XLOOKUP(C5,datos_personales[id:],datos_personales[Apellido:],"no dato",0,1),", ",XLOOKUP(C5,datos_personales[id:],datos_personales[Nombre],"no dato",0,1))} -> amaya, mariela cecilia | G5: {=XLOOKUP(C5,datos_laborales[clave_foranea],datos_laborales[N° De Legajo],"no dato",0,1)} -> 275 | H5: {=XLOOKUP(C5,datos_laborales[clave_foranea], datos_laborales[Inicio Actividad:],"no dato",0,1)} -> 42884 | I5: {=XLOOKUP(C5,datos_laborales[clave_foranea],datos_laborales[Años en Actividad:],"no dato",0,1)} -> 8 | J5: {=XLOOKUP(C5,datos_personales[id:],datos_personales[D.n.i:],"no dato",0,1)} -> 25379033 | K5: {=XLOOKUP(C5,datos_personales[id:],datos_personales[Fecha Nacimiento:],"no dato",0,1)} -> 27877 | L5: =COUNTIF(hijos!B:B,C5) -> 1 | M5: =COUNTIFS(hijos!B:B,C5,hijos!I:I,1) -> 0 | N5: =COUNTIFS(hijos!B:B,C5,hijos!J:J,1) -> 0 | O5: =COUNTIFS(hijos!B:B,C5,hijos!K:K,1) -> 0 | P5: =COUNTIFS(hijos!B:B,C5,hijos!L:L,1) -> 1 | Q5: =SUM(M5:P5) -> 1 | R5: {=XLOOKUP(C5,datos_personales[id:],datos_personales[Tel. Contacto:],"no dato",0,1)} -> 1126921416 | S5: {=XLOOKUP(C5,datos_personales[id:],datos_personales[E-Mail:],"no dato",0,1)} -> marielaceciliaamaya@hotmail.com | T5: {=XLOOKUP(R5,telefonos_afiliados[numeros_loys],telefonos_afiliados[esta],"no esta",0,1)} -> no esta | U5: {=XLOOKUP(C5,datos_personales[id:],datos_laborales[renuncio],"no dato",0,1)} -> #N/A | V5: {=XLOOKUP(C5,datos_laborales[clave_foranea],datos_laborales[tiene_ficha_pdf],"no tiene ficha pdf",0,1)} -> 1
C6: =datos_personales[id:] -> 38184089 | D6: {=XLOOKUP(C6,datos_laborales[clave_foranea],datos_laborales[Relacion de Dependencia],"dato no encontrado",0,1)} -> monotributista | E6: {=XLOOKUP(C6,datos_delegados[clave_foranea:],datos_delegados[En Actividad]," ",0,1)} | F6: {=CONCATENATE(XLOOKUP(C6,datos_personales[id:],datos_personales[Apellido:],"no dato",0,1),", ",XLOOKUP(C6,datos_personales[id:],datos_personales[Nombre],"no dato",0,1))} -> amaya, erika elizabeth | G6: {=XLOOKUP(C6,datos_laborales[clave_foranea],datos_laborales[N° De Legajo],"no dato",0,1)} -> 2914 | H6: {=XLOOKUP(C6,datos_laborales[clave_foranea], datos_laborales[Inicio Actividad:],"no dato",0,1)} -> 45112 | I6: {=XLOOKUP(C6,datos_laborales[clave_foranea],datos_laborales[Años en Actividad:],"no dato",0,1)} -> 2 | J6: {=XLOOKUP(C6,datos_personales[id:],datos_personales[D.n.i:],"no dato",0,1)} -> 38184089 | K6: {=XLOOKUP(C6,datos_personales[id:],datos_personales[Fecha Nacimiento:],"no dato",0,1)} -> 0 | L6: =COUNTIF(hijos!B:B,C6) -> 2 | M6: =COUNTIFS(hijos!B:B,C6,hijos!I:I,1) -> 2 | N6: =COUNTIFS(hijos!B:B,C6,hijos!J:J,1) -> 0 | O6: =COUNTIFS(hijos!B:B,C6,hijos!K:K,1) -> 0 | P6: =COUNTIFS(hijos!B:B,C6,hijos!L:L,1) -> 0 | Q6: =SUM(M6:P6) -> 2 | R6: {=XLOOKUP(C6,datos_personales[id:],datos_personales[Tel. Contacto:],"no dato",0,1)} -> 1127191780 | S6: {=XLOOKUP(C6,datos_personales[id:],datos_personales[E-Mail:],"no dato",0,1)} | T6: {=XLOOKUP(R6,telefonos_afiliados[numeros_loys],telefonos_afiliados[esta],"no esta",0,1)} -> 1 | V6: no tiene en pdf
C7: =datos_personales[id:] -> 38894668 | D7: {=XLOOKUP(C7,datos_laborales[clave_foranea],datos_laborales[Relacion de Dependencia],"dato no encontrado",0,1)} -> monotributista | E7: {=XLOOKUP(C7,datos_delegados[clave_foranea:],datos_delegados[En Actividad]," ",0,1)} | F7: {=CONCATENATE(XLOOKUP(C7,datos_personales[id:],datos_personales[Apellido:],"no dato",0,1),", ",XLOOKUP(C7,datos_personales[id:],datos_personales[Nombre],"no dato",0,1))} -> alegre, daniela | G7: {=XLOOKUP(C7,datos_laborales[clave_foranea],datos_laborales[N° De Legajo],"no dato",0,1)} -> 2238 | H7: {=XLOOKUP(C7,datos_laborales[clave_foranea], datos_laborales[Inicio Actividad:],"no dato",0,1)} -> 45031 | I7: {=XLOOKUP(C7,datos_laborales[clave_foranea],datos_laborales[Años en Actividad:],"no dato",0,1)} -> 2 | J7: {=XLOOKUP(C7,datos_personales[id:],datos_personales[D.n.i:],"no dato",0,1)} -> 38894668 | K7: {=XLOOKUP(C7,datos_personales[id:],datos_personales[Fecha Nacimiento:],"no dato",0,1)} -> 34752 | L7: =COUNTIF(hijos!B:B,C7) -> 1 | M7: =COUNTIFS(hijos!B:B,C7,hijos!I:I,1) -> 0 | N7: =COUNTIFS(hijos!B:B,C7,hijos!J:J,1) -> 0 | O7: =COUNTIFS(hijos!B:B,C7,hijos!K:K,1) -> 1 | P7: =COUNTIFS(hijos!B:B,C7,hijos!L:L,1) -> 0 | Q7: =SUM(M7:P7) -> 1 | R7: {=XLOOKUP(C7,datos_personales[id:],datos_personales[Tel. Contacto:],"no dato",0,1)} -> 1153205634 | S7: {=XLOOKUP(C7,datos_personales[id:],datos_personales[E-Mail:],"no dato",0,1)} -> danielaoriana68@gmail.com | T7: {=XLOOKUP(R7,telefonos_afiliados[numeros_loys],telefonos_afiliados[esta],"no esta",0,1)} -> 1 | U7: {=XLOOKUP(C7,datos_laborales[id:],datos_laborales[renuncio],"no dato",0,1)} -> no dato | V7: no tiene en pdf
C8: =datos_personales[id:] -> 39114453 | D8: {=XLOOKUP(C8,datos_laborales[clave_foranea],datos_laborales[Relacion de Dependencia],"dato no encontrado",0,1)} -> monotributista | E8: {=XLOOKUP(C8,datos_delegados[clave_foranea:],datos_delegados[En Actividad]," ",0,1)} | F8: {=CONCATENATE(XLOOKUP(C8,datos_personales[id:],datos_personales[Apellido:],"no dato",0,1),", ",XLOOKUP(C8,datos_personales[id:],datos_personales[Nombre],"no dato",0,1))} -> ale, micaela ayelen | G8: {=XLOOKUP(C8,datos_laborales[clave_foranea],datos_laborales[N° De Legajo],"no dato",0,1)} -> 1572 | H8: {=XLOOKUP(C8,datos_laborales[clave_foranea], datos_laborales[Inicio Actividad:],"no dato",0,1)} -> 43500 | I8: {=XLOOKUP(C8,datos_laborales[clave_foranea],datos_laborales[Años en Actividad:],"no dato",0,1)} -> 6 | J8: {=XLOOKUP(C8,datos_personales[id:],datos_personales[D.n.i:],"no dato",0,1)} -> 39114453 | K8: {=XLOOKUP(C8,datos_personales[id:],datos_personales[Fecha Nacimiento:],"no dato",0,1)} -> 34957 | L8: =COUNTIF(hijos!B:B,C8) -> 0 | M8: =COUNTIFS(hijos!B:B,C8,hijos!I:I,1) -> 0 | N8: =COUNTIFS(hijos!B:B,C8,hijos!J:J,1) -> 0 | O8: =COUNTIFS(hijos!B:B,C8,hijos!K:K,1) -> 0 | P8: =COUNTIFS(hijos!B:B,C8,hijos!L:L,1) -> 0 | Q8: =SUM(M8:P8) -> 0 | R8: {=XLOOKUP(C8,datos_personales[id:],datos_personales[Tel. Contacto:],"no dato",0,1)} -> 1133985337 | S8: {=XLOOKUP(C8,datos_personales[id:],datos_personales[E-Mail:],"no dato",0,1)} -> micaale40@gmail.com | T8: {=XLOOKUP(R8,telefonos_afiliados[numeros_loys],telefonos_afiliados[esta],"no esta",0,1)} -> 1 | U8: {=XLOOKUP(C8,datos_laborales[id:],datos_laborales[renuncio],"no dato",0,1)} -> no dato | V8: {=XLOOKUP(C8,datos_laborales[clave_foranea],datos_laborales[tiene_ficha_pdf],"no tiene ficha pdf",0,1)} -> no tiene en pdf
C9: =datos_personales[id:] -> 26678242 | D9: {=XLOOKUP(C9,datos_laborales[clave_foranea],datos_laborales[Relacion de Dependencia],"dato no encontrado",0,1)} -> planta transitoria | E9: {=XLOOKUP(C9,datos_delegados[clave_foranea:],datos_delegados[En Actividad]," ",0,1)} | F9: {=CONCATENATE(XLOOKUP(C9,datos_personales[id:],datos_personales[Apellido:],"no dato",0,1),", ",XLOOKUP(C9,datos_personales[id:],datos_personales[Nombre],"no dato",0,1))} -> albornoz, victor omar | G9: {=XLOOKUP(C9,datos_laborales[clave_foranea],datos_laborales[N° De Legajo],"no dato",0,1)} -> 270 | H9: {=XLOOKUP(C9,datos_laborales[clave_foranea], datos_laborales[Inicio Actividad:],"no dato",0,1)} -> 42887 | I9: {=XLOOKUP(C9,datos_laborales[clave_foranea],datos_laborales[Años en Actividad:],"no dato",0,1)} -> 8 | J9: {=XLOOKUP(C9,datos_personales[id:],datos_personales[D.n.i:],"no dato",0,1)} -> 26678242 | K9: {=XLOOKUP(C9,datos_personales[id:],datos_personales[Fecha Nacimiento:],"no dato",0,1)} -> 28848 | L9: =COUNTIF(hijos!B:B,C9) -> 0 | M9: =COUNTIFS(hijos!B:B,C9,hijos!I:I,1) -> 0 | N9: =COUNTIFS(hijos!B:B,C9,hijos!J:J,1) -> 0 | O9: =COUNTIFS(hijos!B:B,C9,hijos!K:K,1) -> 0 | P9: =COUNTIFS(hijos!B:B,C9,hijos!L:L,1) -> 0 | Q9: =SUM(M9:P9) -> 0 | R9: {=XLOOKUP(C9,datos_personales[id:],datos_personales[Tel. Contacto:],"no dato",0,1)} -> 1136163590 | S9: {=XLOOKUP(C9,datos_personales[id:],datos_personales[E-Mail:],"no dato",0,1)} -> albornoz78victor@gmail.com | T9: {=XLOOKUP(R9,telefonos_afiliados[numeros_loys],telefonos_afiliados[esta],"no esta",0,1)} -> no esta | U9: {=XLOOKUP(C9,datos_personales[id:],datos_laborales[renuncio],"no dato",0,1)} -> #N/A | V9: {=XLOOKUP(C9,datos_laborales[clave_foranea],datos_laborales[tiene_ficha_pdf],"no tiene ficha pdf",0,1)} -> no tiene en pdf
C10: =datos_personales[id:] -> 42012262 | D10: {=XLOOKUP(C10,datos_laborales[clave_foranea],datos_laborales[Relacion de Dependencia],"dato no encontrado",0,1)} -> monotributista | E10: {=XLOOKUP(C10,datos_delegados[clave_foranea:],datos_delegados[En Actividad]," ",0,1)} | F10: {=CONCATENATE(XLOOKUP(C10,datos_personales[id:],datos_personales[Apellido:],"no dato",0,1),", ",XLOOKUP(C10,datos_personales[id:],datos_personales[Nombre],"no dato",0,1))} -> acosta, belen teresa | G10: {=XLOOKUP(C10,datos_laborales[clave_foranea],datos_laborales[N° De Legajo],"no dato",0,1)} -> 2166 | H10: {=XLOOKUP(C10,datos_laborales[clave_foranea], datos_laborales[Inicio Actividad:],"no dato",0,1)} -> 0 | I10: {=XLOOKUP(C10,datos_laborales[clave_foranea],datos_laborales[Años en Actividad:],"no dato",0,1)} -> 126 | J10: {=XLOOKUP(C10,datos_personales[id:],datos_personales[D.n.i:],"no dato",0,1)} -> 42012262 | K10: {=XLOOKUP(C10,datos_personales[id:],datos_personales[Fecha Nacimiento:],"no dato",0,1)} -> 36322 | L10: =COUNTIF(hijos!B:B,C10) -> 1 | M10: =COUNTIFS(hijos!B:B,C10,hijos!I:I,1) -> 0 | N10: =COUNTIFS(hijos!B:B,C10,hijos!J:J,1) -> 1 | O10: =COUNTIFS(hijos!B:B,C10,hijos!K:K,1) -> 0 | P10: =COUNTIFS(hijos!B:B,C10,hijos!L:L,1) -> 0 | Q10: =SUM(M10:P10) -> 1 | R10: {=XLOOKUP(C10,datos_personales[id:],datos_personales[Tel. Contacto:],"no dato",0,1)} -> 1128788904 | S10: {=XLOOKUP(C10,datos_personales[id:],datos_personales[E-Mail:],"no dato",0,1)} -> belenmilena1311@hotmail.com | T10: {=XLOOKUP(R10,telefonos_afiliados[numeros_loys],telefonos_afiliados[esta],"no esta",0,1)} -> 1 | U10: {=XLOOKUP(C10,datos_laborales[id:],datos_laborales[renuncio],"no dato",0,1)} -> no dato
C11: =datos_personales[id:] -> 33155103 | D11: {=XLOOKUP(C11,datos_laborales[clave_foranea],datos_laborales[Relacion de Dependencia],"dato no encontrado",0,1)} -> monotributista | E11: {=XLOOKUP(C11,datos_delegados[clave_foranea:],datos_delegados[En Actividad]," ",0,1)} | F11: {=CONCATENATE(XLOOKUP(C11,datos_personales[id:],datos_personales[Apellido:],"no dato",0,1),", ",XLOOKUP(C11,datos_personales[id:],datos_personales[Nombre],"no dato",0,1))} -> romero, irina | G11: {=XLOOKUP(C11,datos_laborales[clave_foranea],datos_laborales[N° De Legajo],"no dato",0,1)} -> 1023 | H11: {=XLOOKUP(C11,datos_laborales[clave_foranea], datos_laborales[Inicio Actividad:],"no dato",0,1)} -> 42948 | I11: {=XLOOKUP(C11,datos_laborales[clave_foranea],datos_laborales[Años en Actividad:],"no dato",0,1)} -> 8 | J11: {=XLOOKUP(C11,datos_personales[id:],datos_personales[D.n.i:],"no dato",0,1)} -> 33155103 | K11: {=XLOOKUP(C11,datos_personales[id:],datos_personales[Fecha Nacimiento:],"no dato",0,1)} -> 31961 | L11: =COUNTIF(hijos!B:B,C11) -> 2 | M11: =COUNTIFS(hijos!B:B,C11,hijos!I:I,1) -> 0 | N11: =COUNTIFS(hijos!B:B,C11,hijos!J:J,1) -> 0 | O11: =COUNTIFS(hijos!B:B,C11,hijos!K:K,1) -> 0 | P11: =COUNTIFS(hijos!B:B,C11,hijos!L:L,1) -> 2 | Q11: =SUM(M11:P11) -> 2 | R11: {=XLOOKUP(C11,datos_personales[id:],datos_personales[Tel. Contacto:],"no dato",0,1)} -> 1165037377 | S11: {=XLOOKUP(C11,datos_personales[id:],datos_personales[E-Mail:],"no dato",0,1)} -> romeroirinauma19@gmail.com | T11: {=XLOOKUP(R11,telefonos_afiliados[numeros_loys],telefonos_afiliados[esta],"no esta",0,1)} -> 1 | U11: {=XLOOKUP(C11,datos_laborales[id:],datos_laborales[renuncio],"no dato",0,1)} -> no dato | V11: {=XLOOKUP(C11,datos_laborales[clave_foranea],datos_laborales[tiene_ficha_pdf],"no tiene ficha pdf",0,1)} -> 1
C12: =datos_personales[id:] -> 35538835 | D12: {=XLOOKUP(C12,datos_laborales[clave_foranea],datos_laborales[Relacion de Dependencia],"dato no encontrado",0,1)} -> monotributista | E12: {=XLOOKUP(C12,datos_delegados[clave_foranea:],datos_delegados[En Actividad]," ",0,1)} | F12: {=CONCATENATE(XLOOKUP(C12,datos_personales[id:],datos_personales[Apellido:],"no dato",0,1),", ",XLOOKUP(C12,datos_personales[id:],datos_personales[Nombre],"no dato",0,1))} -> ruiz, pablo nahuel | G12: {=XLOOKUP(C12,datos_laborales[clave_foranea],datos_laborales[N° De Legajo],"no dato",0,1)} -> 1025 | H12: {=XLOOKUP(C12,datos_laborales[clave_foranea], datos_laborales[Inicio Actividad:],"no dato",0,1)} -> 0 | I12: {=XLOOKUP(C12,datos_laborales[clave_foranea],datos_laborales[Años en Actividad:],"no dato",0,1)} -> 126 | J12: {=XLOOKUP(C12,datos_personales[id:],datos_personales[D.n.i:],"no dato",0,1)} -> 35538835 | K12: {=XLOOKUP(C12,datos_personales[id:],datos_personales[Fecha Nacimiento:],"no dato",0,1)} -> 33586 | L12: =COUNTIF(hijos!B:B,C12) -> 0 | M12: =COUNTIFS(hijos!B:B,C12,hijos!I:I,1) -> 0 | N12: =COUNTIFS(hijos!B:B,C12,hijos!J:J,1) -> 0 | O12: =COUNTIFS(hijos!B:B,C12,hijos!K:K,1) -> 0 | P12: =COUNTIFS(hijos!B:B,C12,hijos!L:L,1) -> 0 | Q12: =SUM(M12:P12) -> 0 | R12: {=XLOOKUP(C12,datos_personales[id:],datos_personales[Tel. Contacto:],"no dato",0,1)} -> 1165851734 | S12: {=XLOOKUP(C12,datos_personales[id:],datos_personales[E-Mail:],"no dato",0,1)} -> nahuelruiz009@gmail.com | T12: {=XLOOKUP(R12,telefonos_afiliados[numeros_loys],telefonos_afiliados[esta],"no esta",0,1)} -> 1 | U12: {=XLOOKUP(C12,datos_laborales[id:],datos_laborales[renuncio],"no dato",0,1)} -> no dato
C13: =datos_personales[id:] -> 93996095 | D13: {=XLOOKUP(C13,datos_laborales[clave_foranea],datos_laborales[Relacion de Dependencia],"dato no encontrado",0,1)} -> monotributista | E13: {=XLOOKUP(C13,datos_delegados[clave_foranea:],datos_delegados[En Actividad]," ",0,1)} | F13: {=CONCATENATE(XLOOKUP(C13,datos_personales[id:],datos_personales[Apellido:],"no dato",0,1),", ",XLOOKUP(C13,datos_personales[id:],datos_personales[Nombre],"no dato",0,1))} -> felipe lima, aidee deysi | G13: {=XLOOKUP(C13,datos_laborales[clave_foranea],datos_laborales[N° De Legajo],"no dato",0,1)} -> 754 | H13: {=XLOOKUP(C13,datos_laborales[clave_foranea], datos_laborales[Inicio Actividad:],"no dato",0,1)} -> 42948 | I13: {=XLOOKUP(C13,datos_laborales[clave_foranea],datos_laborales[Años en Actividad:],"no dato",0,1)} -> 8 | J13: {=XLOOKUP(C13,datos_personales[id:],datos_personales[D.n.i:],"no dato",0,1)} -> 93996095 | K13: {=XLOOKUP(C13,datos_personales[id:],datos_personales[Fecha Nacimiento:],"no dato",0,1)} -> 28260 | L13: =COUNTIF(hijos!B:B,C13) -> 5 | M13: =COUNTIFS(hijos!B:B,C13,hijos!I:I,1) -> 0 | N13: =COUNTIFS(hijos!B:B,C13,hijos!J:J,1) -> 1 | O13: =COUNTIFS(hijos!B:B,C13,hijos!K:K,1) -> 0 | P13: =COUNTIFS(hijos!B:B,C13,hijos!L:L,1) -> 4 | Q13: =SUM(M13:P13) -> 5 | R13: {=XLOOKUP(C13,datos_personales[id:],datos_personales[Tel. Contacto:],"no dato",0,1)} -> 1128666648 | S13: {=XLOOKUP(C13,datos_personales[id:],datos_personales[E-Mail:],"no dato",0,1)} -> aideefelipe1977@gmail.com | T13: {=XLOOKUP(R13,telefonos_afiliados[numeros_loys],telefonos_afiliados[esta],"no esta",0,1)} -> 1 | U13: {=XLOOKUP(C13,datos_laborales[id:],datos_laborales[renuncio],"no dato",0,1)} -> no dato | V13: {=XLOOKUP(C13,datos_laborales[clave_foranea],datos_laborales[tiene_ficha_pdf],"no tiene ficha pdf",0,1)} -> 1
C14: =datos_personales[id:] -> 94842492 | D14: {=XLOOKUP(C14,datos_laborales[clave_foranea],datos_laborales[Relacion de Dependencia],"dato no encontrado",0,1)} -> monotributista | E14: {=XLOOKUP(C14,datos_delegados[clave_foranea:],datos_delegados[En Actividad]," ",0,1)} | F14: {=CONCATENATE(XLOOKUP(C14,datos_personales[id:],datos_personales[Apellido:],"no dato",0,1),", ",XLOOKUP(C14,datos_personales[id:],datos_personales[Nombre],"no dato",0,1))} -> olaya piña, laly del pilar | G14: {=XLOOKUP(C14,datos_laborales[clave_foranea],datos_laborales[N° De Legajo],"no dato",0,1)} -> 527 | H14: {=XLOOKUP(C14,datos_laborales[clave_foranea], datos_laborales[Inicio Actividad:],"no dato",0,1)} -> 0 | I14: {=XLOOKUP(C14,datos_laborales[clave_foranea],datos_laborales[Años en Actividad:],"no dato",0,1)} -> 126 | J14: {=XLOOKUP(C14,datos_personales[id:],datos_personales[D.n.i:],"no dato",0,1)} -> 94842492 | K14: {=XLOOKUP(C14,datos_personales[id:],datos_personales[Fecha Nacimiento:],"no dato",0,1)} -> 33484 | L14: =COUNTIF(hijos!B:B,C14) -> 0 | M14: =COUNTIFS(hijos!B:B,C14,hijos!I:I,1) -> 0 | N14: =COUNTIFS(hijos!B:B,C14,hijos!J:J,1) -> 0 | O14: =COUNTIFS(hijos!B:B,C14,hijos!K:K,1) -> 0 | P14: =COUNTIFS(hijos!B:B,C14,hijos!L:L,1) -> 0 | Q14: =SUM(M14:P14) -> 0 | R14: {=XLOOKUP(C14,datos_personales[id:],datos_personales[Tel. Contacto:],"no dato",0,1)} -> 1154169265 | S14: {=XLOOKUP(C14,datos_personales[id:],datos_personales[E-Mail:],"no dato",0,1)} -> polayalp39@gmail.com | T14: {=XLOOKUP(R14,telefonos_afiliados[numeros_loys],telefonos_afiliados[esta],"no esta",0,1)} -> 1 | U14: {=XLOOKUP(C14,datos_personales[id:],datos_laborales[renuncio],"no dato",0,1)} -> #N/A | V14: {=XLOOKUP(C14,datos_laborales[clave_foranea],datos_laborales[tiene_ficha_pdf],"no tiene ficha pdf",0,1)} -> 1
C15: =datos_personales[id:] -> 95102089 | D15: {=XLOOKUP(C15,datos_laborales[clave_foranea],datos_laborales[Relacion de Dependencia],"dato no encontrado",0,1)} -> monotributista | E15: {=XLOOKUP(C15,datos_delegados[clave_foranea:],datos_delegados[En Actividad]," ",0,1)} -> 1 | F15: {=CONCATENATE(XLOOKUP(C15,datos_personales[id:],datos_personales[Apellido:],"no dato",0,1),", ",XLOOKUP(C15,datos_personales[id:],datos_personales[Nombre],"no dato",0,1))} -> ferro rodriguez, maria elena | G15: {=XLOOKUP(C15,datos_laborales[clave_foranea],datos_laborales[N° De Legajo],"no dato",0,1)} -> 560 | H15: {=XLOOKUP(C15,datos_laborales[clave_foranea], datos_laborales[Inicio Actividad:],"no dato",0,1)} -> 42887 | I15: {=XLOOKUP(C15,datos_laborales[clave_foranea],datos_laborales[Años en Actividad:],"no dato",0,1)} -> 8 | J15: {=XLOOKUP(C15,datos_personales[id:],datos_personales[D.n.i:],"no dato",0,1)} -> 95102089 | K15: {=XLOOKUP(C15,datos_personales[id:],datos_personales[Fecha Nacimiento:],"no dato",0,1)} -> 27698 | L15: =COUNTIF(hijos!B:B,C15) -> 2 | M15: =COUNTIFS(hijos!B:B,C15,hijos!I:I,1) -> 0 | N15: =COUNTIFS(hijos!B:B,C15,hijos!J:J,1) -> 0 | O15: =COUNTIFS(hijos!B:B,C15,hijos!K:K,1) -> 0 | P15: =COUNTIFS(hijos!B:B,C15,hijos!L:L,1) -> 0 | Q15: =SUM(M15:P15) -> 0 | R15: {=XLOOKUP(C15,datos_personales[id:],datos_personales[Tel. Contacto:],"no dato",0,1)} -> 1150420061 | S15: {=XLOOKUP(C15,datos_personales[id:],datos_personales[E-Mail:],"no dato",0,1)} -> marielen1031@hotmail.com | T15: {=XLOOKUP(R15,telefonos_afiliados[numeros_loys],telefonos_afiliados[esta],"no esta",0,1)} -> 1 | U15: {=XLOOKUP(C15,datos_laborales[id:],datos_laborales[renuncio],"no dato",0,1)} -> no dato | V15: {=XLOOKUP(C15,datos_laborales[clave_foranea],datos_laborales[tiene_ficha_pdf],"no tiene ficha pdf",0,1)} -> 1
C16: =datos_personales[id:] -> 95189729 | D16: {=XLOOKUP(C16,datos_laborales[clave_foranea],datos_laborales[Relacion de Dependencia],"dato no encontrado",0,1)} -> monotributista | E16: {=XLOOKUP(C16,datos_delegados[clave_foranea:],datos_delegados[En Actividad]," ",0,1)} | F16: {=CONCATENATE(XLOOKUP(C16,datos_personales[id:],datos_personales[Apellido:],"no dato",0,1),", ",XLOOKUP(C16,datos_personales[id:],datos_personales[Nombre],"no dato",0,1))} -> gutierrez quispe, griselda | G16: {=XLOOKUP(C16,datos_laborales[clave_foranea],datos_laborales[N° De Legajo],"no dato",0,1)} -> 909 | H16: {=XLOOKUP(C16,datos_laborales[clave_foranea], datos_laborales[Inicio Actividad:],"no dato",0,1)} -> 42948 | I16: {=XLOOKUP(C16,datos_laborales[clave_foranea],datos_laborales[Años en Actividad:],"no dato",0,1)} -> 8 | J16: {=XLOOKUP(C16,datos_personales[id:],datos_personales[D.n.i:],"no dato",0,1)} -> 95189729 | K16: {=XLOOKUP(C16,datos_personales[id:],datos_personales[Fecha Nacimiento:],"no dato",0,1)} -> 30644 | L16: =COUNTIF(hijos!B:B,C16) -> 5 | M16: =COUNTIFS(hijos!B:B,C16,hijos!I:I,1) -> 0 | N16: =COUNTIFS(hijos!B:B,C16,hijos!J:J,1) -> 0 | O16: =COUNTIFS(hijos!B:B,C16,hijos!K:K,1) -> 2 | P16: =COUNTIFS(hijos!B:B,C16,hijos!L:L,1) -> 3 | Q16: =SUM(M16:P16) -> 5 | R16: {=XLOOKUP(C16,datos_personales[id:],datos_personales[Tel. Contacto:],"no dato",0,1)} -> 1124936411 | S16: {=XLOOKUP(C16,datos_personales[id:],datos_personales[E-Mail:],"no dato",0,1)} -> chiiguisguty@gmain.com | T16: {=XLOOKUP(R16,telefonos_afiliados[numeros_loys],telefonos_afiliados[esta],"no esta",0,1)} -> 1 | U16: {=XLOOKUP(C16,datos_laborales[id:],datos_laborales[renuncio],"no dato",0,1)} -> no dato | V16: {=XLOOKUP(C16,datos_laborales[clave_foranea],datos_laborales[tiene_ficha_pdf],"no tiene ficha pdf",0,1)} -> 1
